Workbook

Sheet Dashboard
A1: LU | B1: Doel | C1: Behaald | D1: Sprint 1 | E1: Sprint 2 | F1: Sprint 3 | G1: Sprint 4 | H1: Sprint 5 | I1: Sprint 6 | J1: Sprint 7 | K1: Sprint 8
A2: LU 1: Impact | B2: 2 | C2: =COUNTIF(D2:K2, "V") -> 2 | D2: =Logboek!C18 -> V | E2: =Logboek!C46 -> - | F2: =Logboek!C74 -> V | G2: =Logboek!C102 -> - | H2: =Logboek!C130 -> - | I2: =Logboek!C158 -> - | J2: =Logboek!C186 -> - | K2: =Logboek!C214 -> -
A3: LU 2: Oplossing | B3: 4 | C3: =COUNTIF(D3:K3, "V") -> 3 | D3: =Logboek!C19 -> V | E3: =Logboek!C47 -> V | F3: =Logboek!C75 -> V | G3: =Logboek!C103 -> - | H3: =Logboek!C131 -> - | I3: =Logboek!C159 -> - | J3: =Logboek!C187 -> - | K3: =Logboek!C215 -> -
A4: LU 3: Ethiek | B4: 2 | C4: =COUNTIF(D4:K4, "V") -> 0 | D4: =Logboek!C20 -> - | E4: =Logboek!C48 -> - | F4: =Logboek!C76 -> - | G4: =Logboek!C104 -> - | H4: =Logboek!C132 -> - | I4: =Logboek!C160 -> - | J4: =Logboek!C188 -> - | K4: =Logboek!C216 -> -
A5: LU 4: Tools | B5: 4 | C5: =COUNTIF(D5:K5, "V") -> 3 | D5: =Logboek!C21 -> V | E5: =Logboek!C49 -> V | F5: =Logboek!C77 -> V | G5: =Logboek!C105 -> - | H5: =Logboek!C133 -> - | I5: =Logboek!C161 -> - | J5: =Logboek!C189 -> - | K5: =Logboek!C217 -> -
A6: LU 5: Zelfsturing | B6: 6 | C6: =COUNTIF(D6:K6, "V") -> 3 | D6: =Logboek!C22 -> V | E6: =Logboek!C50 -> V | F6: =Logboek!C78 -> V | G6: =Logboek!C106 -> - | H6: =Logboek!C134 -> - | I6: =Logboek!C162 -> - | J6: =Logboek!C190 -> - | K6: =Logboek!C218 -> -
A7: Totaal | B7: =SUM(B2:B6) -> 18 | C7: =SUM(D6:K7) -> 11 | D7: =COUNTIF(D2:D6, "V") -> 4 | E7: =COUNTIF(E2:E6, "V") -> 3 | F7: =COUNTIF(F2:F6, "V") -> 4 | G7: =COUNTIF(G2:G6, "V") -> 0 | H7: =COUNTIF(H2:H6, "V") -> 0 | I7: =COUNTIF(I2:I6, "V") -> 0 | J7: =COUNTIF(J2:J6, "V") -> 0 | K7: =COUNTIF(K2:K6, "V") -> 0
A9: Portfolio | B9: https://persoonlijk-portfolio.vercel.app/

Sheet Logboek
A1: SPRINT 1
A3: 1. PLANNING (User Stories) | D3: Plannen met je plannings Agent
A4: Story | B4: Story Omschrijving | C4: Acceptatie Criteria | D4: Kwaliteitscriteria
A5: RS | B5: Als aankomend project- en organisatieprofessional, wil ik onderzoeken welke AI-toepassingen de meeste impact hebben op organiseren, coördineren en samenwerken, zodat ik weet hoe mijn toekomstige rol, taken en vaardigheden veranderen. | C5: 1. Prompting: Een tweetrapsaanpak uitvoeren: eerst bronnen zoeken via Perplexity (minstens 4 typen), daarna via een deep-research-prompt het verslag genereren met CoT en bronvermelding. 2. Verslag: Een compleet onderzoeksverslag opleveren met vaste onderdelen: samenvatting, inleiding, methode, resultaten, risico's, conclusie en aanbevelingen. 3. Methode: Kwalitatief literatuuronderzoek doen met narratieve synthese op basis van 10 bronnen. 4. Presentatie: De belangrijkste inzichten presenteren tijdens de Show & Grow. | D5: 1. Promptopbouw: Prompts bevatten vooraf een duidelijke rol, context, randvoorwaarden en gewenst format. 2. Bronnen: Minimaal 10 bronnen uit minstens 4 invalshoeken; gecheckt en gecorrigeerd volgens APA7-normen. 3. Toolkeuze: Bewuste keuze vastleggen voor OpenAI (onderzoek/synthese) en Claude (vormgeving/structuur). 4. Triangulatie: Bevindingen vergelijken tussen modellen (Gemini en OpenAI) en noteren waarom bepaalde output niet bruikbaar is. 5. Kritische blik: Conclusie onderbouwen met risico's (betrouwbaarheid en afhankelijkheid) en AI positioneren als assistent, niet als vervanging.
A6: US | B6: Als student in de minor Futureproof met AI, wil ik mijn eigen portfoliowebsite bouwen en online publiceren, zodat coaches en medestudenten direct zien wie ik ben en hoe ik aan de leeruitkomsten werk. | C6: 1. Homepage: Toont mijn profiel, de context van de minor en mijn focus op organiseren en samenwerken. 2. Over mij: Bevat een profielfoto, achtergrond, studieloopbaan en interesses (geen placeholderteksten). 3. Sprints & bewijzen: Bevat een actueel sprintoverzicht en een directe link naar het onderzoeksverslag (RS), gekoppeld aan LU1 en LU4. 4. Navigatie: Menu werkt soepel tussen Home, Over mij, Leeruitkomsten, Sprints, Bewijzen en Contact. 5. Livegang: De website is publiek bereikbaar via een werkende Vercel-link. | D6: 1. Responsiveness: Lay-out werkt goed op zowel iPhone als desktop zonder afsnijdingen of horizontaal scrollen. 2. Code & Deployment: Codebeheer via GitHub en automatische livegang via Vercel geregeld. 3. Taal & links: Teksten zijn foutloos geschreven; alle knoppen en links werken zonder foutmeldingen. 4. Vormgeving: Rustige, warme kleuren en typografie die een professioneel geheel vormen en afwijken van standaard AI-templates. 5. Transparantie: Duidelijk vermeld waar AI is ingezet en wat eigen werk is.
A7: LS | B7: Als student in de minor Futureproof met AI, wil ik leren werken met Claude Code, prompting en vibe-coding via GitHub en Vercel om een normchecker-prototype te bouwen, zodat ik ontdek wat AI al weet over ISO- en NEN-normen en zelfstandig een interactief frontend-prototype online kan publiceren. | C7: 1. Kennisverkenning: Via gerichte prompts testen wat Claude Code inhoudelijk weet over NEN- en ISO-normen en welke structuur het model voorstelt. 2. Dashboard-prototype: Een voorbeeld-dashboard (normchecker) bouwen op basis van een fictieve persona om de werking van normcontroles te visualiseren. 3. Deployment: De applicatie via Claude Code en GitHub live publiceren op een werkende Vercel-omgeving (normchecker.vercel.app). | D7: 1. Promptstructuur: Prompts aan Claude Code zijn voorzien van duidelijke rolinstructies, domeincontext (bouw/normen) en gewenste output-structuren. 2. Inhoudelijke toetsing: Controleren of de voorgestelde NEN/ISO-structuren door Claude Code inhoudelijk kloppen en geen hallucinaties bevatten. 3. Pipeline-stabiliteit: De koppeling tussen lokale bestanden, GitHub-repository en Vercel werkt zonder build-fouten.
A11: 2. FEEDBACK (Ontvangen van anderen)
A12: Datum | B12: Van wie | C12: Feedback | D12: Jouw actie
A16: 3. ZELFEVALUATIE (Mastery)
A17: LU | B17: Leeruitkomst | C17: Niveau | D17: Argumentatie en bewijs
A18: LU 1 | B18: AI-impact op de beroepspraktijk analyseren en evalueren | C18: V | D18: In mijn onderzoeksverslag "De toekomst van de Project- en organisatieprofessional in het tijdperk van generatieve AI" onderzocht ik welke AI-toepassingen effect hebben op organiseren, coördineren en samenwerken. Ik werkte met tien bronnen uit vier verschillende soorten bronnen en liet het verslag schrijven met OpenAI Deep Research, met aparte hoofdstukken over taakverschuiving, nieuwe vaardigheden en risico's. Dat laat zien dat ik niet alleen weet wát er verandert in mijn vakgebied, maar ook welke vaardigheden ik daardoor zelf nodig ga hebben.
A19: LU 2 | B19: Praktijkgerichte AI oplossing ontwerpen, realiseren en presenteren | C19: V | D19: N.v.t
A20: LU 3 | B20: Ethiek en verantwoordelijk AI-gebruik beoordelen | C20: - | D20: N.v.t
A21: LU 4 | B21: AI Tools en technieken gebruiken | C21: V | D21: Bij elk van de drie projecten koos ik een andere tool voor een andere taak, in plaats van steeds hetzelfde model te gebruiken. Voor het onderzoek gebruikte ik Perplexity om bronnen te zoeken, OpenAI Deep Research om te schrijven, Gemini om te vergelijken en Claude om de tekst af te werken. Voor de portfoliowebsite gebruikte ik Google AI Studio om snel te proberen, Claude om de code te verbeteren, en Visual Studio Code met GitHub en Vercel om de site echt te bouwen en live te zetten. Voor NormChecker gebruikte ik Claude Code om te testen wat het al wist over NEN- en ISO-bouwnormen, en weer GitHub en Vercel om het live te zetten. Drie projecten, drie keer een andere combinatie van tools, steeds gekozen op basis van wat de taak nodig had.
A22: LU 5 | B22: Zelfstandig en zelfsturend werken | C22: V | D22: Bij het onderzoek besloot ik zelf om de uitkomst van Gemini te vergelijken met die van OpenAI, en verwierp ik die bewust toen bleek dat de kwaliteit niet goed genoeg was. Ook liep ik zelf de bronnenlijst na en verbeterde ik drie fouten. Bij de portfoliowebsite koos ik zelf mijn eigen leerpad in tools: eerst Google AI Studio om te verkennen, dan Claude voor de stijl, en pas daarna Visual Studio Code, GitHub en Vercel voor echt beheer. Ik testte de site ook zelf op mobiel en desktop voordat ik hem als af beschouwde. Bij NormChecker koos ik zelf het onderwerp, gebaseerd op iets wat ik in de praktijk was tegengekomen, en besloot ik zelf om het klein te houden als oefening in plaats van meteen een af product na te streven. In alle drie de projecten stelde ik dus zelf de koers, zonder dat iemand mij een vast stappenplan gaf.
A24: 4. REFLECTIE
A25: Datum | B25: Wat heb je geleerd? | C25: Wat behoud je? | D25: Wat ga je anders doen?
A26: 46281 | B26: Websites zoals NEN Connect bevatten veel juridische regels. Daardoor bleek mijn idee niet haalbaar. Na sparren met Jan heb ik het losgelaten. Ik heb geleerd dat je soms hele leuke ideeën hebt, maar dat je sommige dingen moet loslaten omdat ze niet haalbaar zijn. | C26: Sparren met mijn coach over mijn ideeën en kritisch blijven op wat bronnen en AI voorstellen. | D26: Bij een nieuw idee eerst de haalbaarheid uitzoeken (juridisch en welke informatie ik mag gebruiken), voordat ik veel tijd in het uitwerken steek. Een idee sneller loslaten als het niet kan.
A27: 46281 | B27: Ik heb via Jan contact opgenomen met Dotslash om meer uit mijn minor te halen en te vragen naar een opdracht. Ik heb geleerd dat je moet durven vragen. | C27: Zelf contact zoeken en vragen stellen. | D27: Eerder en vaker zelf vragen stellen aan coaches en organisaties, in plaats van te wachten op een opdracht.
A28: 46281 | B28: AI wordt in mijn beroep steeds belangrijker en iedereen moet het leren. Het fysieke contact met mensen blijft belangrijk en wordt misschien nog belangrijker. | C28: AI gebruiken als assistent en niet als vervanging, en bewust kiezen welke tool bij welke taak past. | D28: Naast AI-vaardigheden ook blijven ontwikkelen wat AI niet kan overnemen, zoals samenwerken en persoonlijk contact.
A29: SPRINT 2
A31: 1. PLANNING (User Stories) | D31: Plannen met je plannings Agent
A32: Story | B32: Story Omschrijving | C32: Acceptatie Criteria | D32: Kwaliteitscriteria
A33: LS | B33: Als student in de minor Futureproof met AI, wil ik de basisprincipes en architecturen van AI-agents leren via DataCamp, zodat ik kan onderbouwen of en hoe een agentic aanpak waarde toevoegt aan mijn specifieke minoroplossing. | C33: 1. DataCamp-cursus "Introduction to AI Agents" succesvol afgerond, inclusief certificaat/bewijs van afronding in logboek. 2. Een geschreven samenvatting waar de stof besproken wordt en je ten alle tijden de stof terug kan vinden 3. De samenvatting is toegevoegd aan mijn portfolio om deze altijd bij de hand te hebben. | D33: 1. Betrouwbaarheid & herkomst: gebruik van actuele, gereputeerde bronnen en correcte bronvermelding. 2. Diepgang & onderbouwing: helder onderscheid gemaakt tussen eenvoudige prompt-chains/workflows en daadwerkelijke autonome agents. 3. Toepasbaarheid: de vertaalslag sluit direct aan op de context van het eigen projectportfolio.
A34: RS | B34: Als AI-projectmanager in opleiding, wil ik de bedrijfsactiviteiten, laadinfrastructuur-diensten en potentiële AI-kansen van Blue Current onderzoeken, zodat ik tijdens het eerste intakegesprek direct gerichte AI-use cases kan pitchen en een scherpe minoropdracht kan formuleren (Leeruitkomst: Impact & Oplossing). | C34: 1. Een compact onderzoeksverslag met daarin de kernactiviteiten en propositie van Blue Current, en de huidige technologie- en laadinfrastructuurcontext. 2. Minimaal 3 concrete AI-kansen/use cases uitgewerkt (bijv. slim laden/netcongestie, voorspellend onderhoud, geautomatiseerde support). 3. Een gestructureerde vragenlijst (5–8 vragen) voor het intakegesprek met Blue Current. | D34: 1. Bronnen & herkomst: relevante openbare bronnen gebruikt (website, nieuws, LinkedIn) met expliciete bronvermelding. 2. Triangulatie: deskresearch gecombineerd met gerichte analyse via minimaal één LLM met een gestructureerde prompt-opbouw. 3. Relevantie & haalbaarheid: de aangedragen AI-kansen sluiten realistisch aan op de context van een minorproject van ca. 4 maanden.
A35: US | B35: Als student van de minor Future Proof met AI, wil ik het eerste werkende prototype van de vernieuwde website en de gebruikte AI-systemen presenteren aan Ronald Boiten, zodat we kunnen toetsen of het ontwerp en de kleuren aansluiten bij zijn grafische identiteit en we duidelijke input hebben voor Sprint 3. | C35: 1. Het prototype is live en toegankelijk via de Vercel-link. 2. De specifieke grafische stijl en de kleurstelling van Ronald zijn herkenbaar doorgevoerd op de website. 3. De boekprojecten zijn visueel representatief weergegeven. 4. De afspraak en presentatie op dinsdag 27 september zijn uitgevoerd. 5. De feedback van Ronald is gedocumenteerd als input voor Sprint 3. | D35: 1. Er is een heldere toelichting gegeven over de gebruikte AI-tools en -systemen. 2. De Vercel-link werkt technisch goed en is responsive op zowel mobiel als desktop. 3. De opzet en code van de website zijn netjes gestructureerd en onderhoudbaar voor verdere uitbreiding in Sprint 3.
A39: 2. FEEDBACK (Ontvangen van anderen)
A40: Datum | B40: Van wie | C40: Feedback | D40: Jouw actie
A41: 46288 | B41: Shahmeer | C41: Zoek uit wat je daarvoor kan doen met AI. Stuur nog een mail naar Norm. Leer je basis via datacamp. Onderzoek of de website echt nodig is om te verbeteren | D41: Op advies ga ik een mail sturen en kijken of ik reactie kan ontvangen. Verder zorg ik dat ik mij nog meer ga verdiepen door middel van Datacamp
A42: 46292 | B42: Ronald Boiten | C42: Ik vind het fijn dat mijn werk nu veel duidelijker naar voren komt.De fotografie mag inderdaad groter, maar niet te gelikt. Hou de teksten kort. Ik wil wel mijn hele oeuvre kunnen blijven tonen.De typografie moet echt kloppen. | D42: In de volgende sprint staat gebruikersvalidatie centraal. Ik test de eerste redesign met de eigenaar, verwerk feedback op visuele identiteit, content en gebruikservaring en werk de homepage responsive en inhoudelijk correct uit. Pas na goedkeuring van de visuele frontend start ik met de technische beheeromgeving en backend.
A44: 3. ZELFEVALUATIE (Mastery)
A45: LU | B45: Leeruitkomst | C45: Niveau | D45: Argumentatie en bewijs
A46: LU 1 | B46: AI-impact op de beroepspraktijk analyseren en evalueren | C46: -
A47: LU 2 | B47: Praktijkgerichte AI oplossing ontwerpen, realiseren en presenteren | C47: V | D47: In Sprint 2 leverde ik het eerste werkende prototype van mijn vernieuwde portfoliowebsite op en presenteerde ik dit, samen met de gebruikte AI-systemen, aan Ronald Boiten. Ik liet zien hoe zijn grafische stijl en kleurgebruik in het ontwerp waren verwerkt en welke AI-tools ik daarvoor had ingezet. Ronald gaf concrete feedback op de fotografie, de teksten en de typografie, die ik direct heb vertaald naar aanpassingen voor Sprint 3. Daarmee heb ik niet alleen een praktijkgerichte AI-oplossing gerealiseerd, maar deze ook daadwerkelijk gepresenteerd aan een echte opdrachtgever en verwerkt in een concreet vervolgplan.
A48: LU 3 | B48: Ethiek en verantwoordelijk AI-gebruik beoordelen | C48: -
A49: LU 4 | B49: AI Tools en technieken gebruiken | C49: V | D49: Ook in Sprint 2 koos ik per taak een andere tool. Voor de Learning Story rondom AI-agents volgde ik de DataCamp-cursus "Introduction to AI Agents" en vergeleek ik een agentic aanpak met mijn huidige werkwijze. Voor het onderzoek naar Blue Current combineerde ik deskresearch met een LLM om gerichte AI-kansen te formuleren voor het intakegesprek. Voor het prototype van de portfoliowebsite gebruikte ik opnieuw Visual Studio Code, GitHub en Vercel om de website live te zetten, en liet ik het resultaat beoordelen door Ronald Boiten. Zo zette ik per onderdeel bewust de tool in die het beste bij de taak paste.
A50: LU 5 | B50: Zelfstandig en zelfsturend werken | C50: V | D50: Ik stuurde Sprint 2 grotendeels zelf aan. Ik koos zelf de DataCamp-cursus om mijn kennis over AI-agents te verdiepen, plande zelf het onderzoek naar Blue Current en de bijbehorende vragenlijst, en regelde zelfstandig de afspraak met Ronald Boiten om het prototype te bespreken. Na de feedback van Shahmeer en Ronald bepaalde ik zelf mijn vervolgstappen: eerst gebruikersvalidatie van het ontwerp, daarna pas de technische beheeromgeving. Ik hield dus zelf overzicht over mijn planning en stuurde bij op basis van de feedback die ik kreeg, zonder dat iemand mij een vast stappenplan gaf.
A52: 4. REFLECTIE
A53: Datum | B53: Wat heb je geleerd? | C53: Wat behoud je? | D53: Wat ga je anders doen?
A54: 46294 | B54: AI-agents zijn heel belangrijk en er valt heel veel over te leren. Ik heb de basis geleerd via DataCamp, maar ik heb het idee dat ik er nog lang niet alles uit heb gehaald. | C54: Eerst de basis leren via een cursus (DataCamp) voordat ik iets ga bouwen. | D54: Mij verder verdiepen in AI-agents en uitzoeken wat ik in mijn eigen opdracht kan gebruiken. De keuze voor een agent-aanpak onderbouwen met een aparte Research Story.
...

Sheet Lijsten
A1: - | B1: US
A2: O | B2: LS
A3: V | B3: RS
